Here is the unit test for the 'add' method that expects the correct result, but will fail due to the intentional error in the implementation:

import unittest

from calculator import Calculator

class TestCalculator(unittest.TestCase):
    def test_add(self):
        calculator = Calculator()
        result = calculator.add(2, 3)
        self.assertEqual(result, 6)

if __name__ == '__main__':
    unittest.main()